INFO:discord.client:logging in using static token
INFO:discord.gateway:Shard ID None has connected to Gateway (Session ID: f0d3c02c0fd91fb8215e7f54d0005969).
ERROR:discord.app_commands.tree:Ignoring exception in command 'toggle_hourly_phrase'
Traceback (most recent call last):
  File "C:\Users\kingo\AppData\Local\Packages\PythonSoftwareFoundation.Python.3.11_qbz5n2kfra8p0\LocalCache\local-packages\Python311\site-packages\discord\app_commands\commands.py", line 827, in _do_call
    return await self._callback(self.binding, interaction, **params)  # type: ignore
           ^^^^^^^^^^^^^^^^^^^^^^^^^^^^^^^^^^^^^^^^^^^^^^^^^^^^^^^^^
  File "c:\Users\kingo\trans_resource_bot\bot.py", line 115, in toggle_hourly_phrase
    await MyCog.send_hourly_message(self,ctx,-1)
  File "c:\Users\kingo\trans_resource_bot\bot.py", line 102, in send_hourly_message
    await ctx.response.send_message("Error: State is already set to on/off")
  File "C:\Users\kingo\AppData\Local\Packages\PythonSoftwareFoundation.Python.3.11_qbz5n2kfra8p0\LocalCache\local-packages\Python311\site-packages\discord\interactions.py", line 774, in send_message
    raise InteractionResponded(self._parent)
discord.errors.InteractionResponded: This interaction has already been responded to before

The above exception was the direct cause of the following exception:

Traceback (most recent call last):
  File "C:\Users\kingo\AppData\Local\Packages\PythonSoftwareFoundation.Python.3.11_qbz5n2kfra8p0\LocalCache\local-packages\Python311\site-packages\discord\app_commands\tree.py", line 1248, in _call
    await command._invoke_with_namespace(interaction, namespace)
  File "C:\Users\kingo\AppData\Local\Packages\PythonSoftwareFoundation.Python.3.11_qbz5n2kfra8p0\LocalCache\local-packages\Python311\site-packages\discord\app_commands\commands.py", line 853, in _invoke_with_namespace
    return await self._do_call(interaction, transformed_values)
           ^^^^^^^^^^^^^^^^^^^^^^^^^^^^^^^^^^^^^^^^^^^^^^^^^^^^
  File "C:\Users\kingo\AppData\Local\Packages\PythonSoftwareFoundation.Python.3.11_qbz5n2kfra8p0\LocalCache\local-packages\Python311\site-packages\discord\app_commands\commands.py", line 846, in _do_call
    raise CommandInvokeError(self, e) from e
discord.app_commands.errors.CommandInvokeError: Command 'toggle_hourly_phrase' raised an exception: InteractionResponded: This interaction has already been responded to before
ERROR:discord.app_commands.tree:Ignoring exception in command 'toggle_hourly_phrase'
Traceback (most recent call last):
  File "C:\Users\kingo\AppData\Local\Packages\PythonSoftwareFoundation.Python.3.11_qbz5n2kfra8p0\LocalCache\local-packages\Python311\site-packages\discord\app_commands\commands.py", line 827, in _do_call
    return await self._callback(self.binding, interaction, **params)  # type: ignore
           ^^^^^^^^^^^^^^^^^^^^^^^^^^^^^^^^^^^^^^^^^^^^^^^^^^^^^^^^^
  File "c:\Users\kingo\trans_resource_bot\bot.py", line 115, in toggle_hourly_phrase
    await MyCog.send_hourly_message(self,ctx,-1)
  File "c:\Users\kingo\trans_resource_bot\bot.py", line 102, in send_hourly_message
    await ctx.response.send_message("Error: State is already set to on/off")
  File "C:\Users\kingo\AppData\Local\Packages\PythonSoftwareFoundation.Python.3.11_qbz5n2kfra8p0\LocalCache\local-packages\Python311\site-packages\discord\interactions.py", line 774, in send_message
    raise InteractionResponded(self._parent)
discord.errors.InteractionResponded: This interaction has already been responded to before

The above exception was the direct cause of the following exception:

Traceback (most recent call last):
  File "C:\Users\kingo\AppData\Local\Packages\PythonSoftwareFoundation.Python.3.11_qbz5n2kfra8p0\LocalCache\local-packages\Python311\site-packages\discord\app_commands\tree.py", line 1248, in _call
    await command._invoke_with_namespace(interaction, namespace)
  File "C:\Users\kingo\AppData\Local\Packages\PythonSoftwareFoundation.Python.3.11_qbz5n2kfra8p0\LocalCache\local-packages\Python311\site-packages\discord\app_commands\commands.py", line 853, in _invoke_with_namespace
    return await self._do_call(interaction, transformed_values)
           ^^^^^^^^^^^^^^^^^^^^^^^^^^^^^^^^^^^^^^^^^^^^^^^^^^^^
  File "C:\Users\kingo\AppData\Local\Packages\PythonSoftwareFoundation.Python.3.11_qbz5n2kfra8p0\LocalCache\local-packages\Python311\site-packages\discord\app_commands\commands.py", line 846, in _do_call
    raise CommandInvokeError(self, e) from e
discord.app_commands.errors.CommandInvokeError: Command 'toggle_hourly_phrase' raised an exception: InteractionResponded: This interaction has already been responded to before
WARNING:discord.gateway:Shard ID None has stopped responding to the gateway. Closing and restarting.
INFO:discord.gateway:Shard ID None session has been invalidated.
INFO:discord.gateway:Shard ID None has connected to Gateway (Session ID: 85b4bff9ec8089bb32eda3342d37b2c7).
WARNING:discord.gateway:Shard ID None has stopped responding to the gateway. Closing and restarting.
INFO:discord.gateway:Shard ID None session has been invalidated.
INFO:discord.gateway:Shard ID None has connected to Gateway (Session ID: 45869413093b2ad9b0a0ec51992511b2).
WARNING:discord.gateway:Can't keep up, shard ID None websocket is 49.6s behind.
ERROR:discord.app_commands.tree:Ignoring exception in command 'toggle_hourly_phrase'
Traceback (most recent call last):
  File "C:\Users\kingo\AppData\Local\Packages\PythonSoftwareFoundation.Python.3.11_qbz5n2kfra8p0\LocalCache\local-packages\Python311\site-packages\discord\app_commands\commands.py", line 827, in _do_call
    return await self._callback(self.binding, interaction, **params)  # type: ignore
           ^^^^^^^^^^^^^^^^^^^^^^^^^^^^^^^^^^^^^^^^^^^^^^^^^^^^^^^^^
  File "c:\Users\kingo\trans_resource_bot\bot.py", line 109, in toggle_hourly_phrase
    await MyCog.send_hourly_message(self,ctx,1)
  File "c:\Users\kingo\trans_resource_bot\bot.py", line 92, in send_hourly_message
    await ctx.response.send_message(":transgender_symbol: Trans Rights! :transgender_flag:")
  File "C:\Users\kingo\AppData\Local\Packages\PythonSoftwareFoundation.Python.3.11_qbz5n2kfra8p0\LocalCache\local-packages\Python311\site-packages\discord\interactions.py", line 774, in send_message
    raise InteractionResponded(self._parent)
discord.errors.InteractionResponded: This interaction has already been responded to before

The above exception was the direct cause of the following exception:

Traceback (most recent call last):
  File "C:\Users\kingo\AppData\Local\Packages\PythonSoftwareFoundation.Python.3.11_qbz5n2kfra8p0\LocalCache\local-packages\Python311\site-packages\discord\app_commands\tree.py", line 1248, in _call
    await command._invoke_with_namespace(interaction, namespace)
  File "C:\Users\kingo\AppData\Local\Packages\PythonSoftwareFoundation.Python.3.11_qbz5n2kfra8p0\LocalCache\local-packages\Python311\site-packages\discord\app_commands\commands.py", line 853, in _invoke_with_namespace
    return await self._do_call(interaction, transformed_values)
           ^^^^^^^^^^^^^^^^^^^^^^^^^^^^^^^^^^^^^^^^^^^^^^^^^^^^
  File "C:\Users\kingo\AppData\Local\Packages\PythonSoftwareFoundation.Python.3.11_qbz5n2kfra8p0\LocalCache\local-packages\Python311\site-packages\discord\app_commands\commands.py", line 846, in _do_call
    raise CommandInvokeError(self, e) from e
discord.app_commands.errors.CommandInvokeError: Command 'toggle_hourly_phrase' raised an exception: InteractionResponded: This interaction has already been responded to before
ERROR:discord.app_commands.tree:Ignoring exception in command 'toggle_hourly_phrase'
Traceback (most recent call last):
  File "C:\Users\kingo\AppData\Local\Packages\PythonSoftwareFoundation.Python.3.11_qbz5n2kfra8p0\LocalCache\local-packages\Python311\site-packages\discord\app_commands\commands.py", line 827, in _do_call
    return await self._callback(self.binding, interaction, **params)  # type: ignore
           ^^^^^^^^^^^^^^^^^^^^^^^^^^^^^^^^^^^^^^^^^^^^^^^^^^^^^^^^^
  File "c:\Users\kingo\trans_resource_bot\bot.py", line 109, in toggle_hourly_phrase
    await MyCog.send_hourly_message(self,ctx,1)
  File "c:\Users\kingo\trans_resource_bot\bot.py", line 92, in send_hourly_message
    await ctx.response.send_message(":transgender_symbol: Trans Rights! :transgender_flag:")
  File "C:\Users\kingo\AppData\Local\Packages\PythonSoftwareFoundation.Python.3.11_qbz5n2kfra8p0\LocalCache\local-packages\Python311\site-packages\discord\interactions.py", line 774, in send_message
    raise InteractionResponded(self._parent)
discord.errors.InteractionResponded: This interaction has already been responded to before

The above exception was the direct cause of the following exception:

Traceback (most recent call last):
  File "C:\Users\kingo\AppData\Local\Packages\PythonSoftwareFoundation.Python.3.11_qbz5n2kfra8p0\LocalCache\local-packages\Python311\site-packages\discord\app_commands\tree.py", line 1248, in _call
    await command._invoke_with_namespace(interaction, namespace)
  File "C:\Users\kingo\AppData\Local\Packages\PythonSoftwareFoundation.Python.3.11_qbz5n2kfra8p0\LocalCache\local-packages\Python311\site-packages\discord\app_commands\commands.py", line 853, in _invoke_with_namespace
    return await self._do_call(interaction, transformed_values)
           ^^^^^^^^^^^^^^^^^^^^^^^^^^^^^^^^^^^^^^^^^^^^^^^^^^^^
  File "C:\Users\kingo\AppData\Local\Packages\PythonSoftwareFoundation.Python.3.11_qbz5n2kfra8p0\LocalCache\local-packages\Python311\site-packages\discord\app_commands\commands.py", line 846, in _do_call
    raise CommandInvokeError(self, e) from e
discord.app_commands.errors.CommandInvokeError: Command 'toggle_hourly_phrase' raised an exception: InteractionResponded: This interaction has already been responded to before
INFO:discord.gateway:Shard ID None session has been invalidated.
INFO:discord.gateway:Shard ID None has connected to Gateway (Session ID: 1ce1f638e0633bd65f1e519192bd813a).
WARNING:discord.gateway:Shard ID None has stopped responding to the gateway. Closing and restarting.
INFO:discord.gateway:Shard ID None session has been invalidated.
INFO:discord.gateway:Shard ID None has connected to Gateway (Session ID: 7526c2515f308453ea996f377c7afc8e).
INFO:discord.gateway:Shard ID None has successfully RESUMED session 7526c2515f308453ea996f377c7afc8e.
